Traceback (most recent call last):
  File "C:\Users\samia\Downloads\Anaconda\lib\site-packages\jupyter_cache\executors\utils.py", line 51, in single_nb_execution
    executenb(
  File "C:\Users\samia\Downloads\Anaconda\lib\site-packages\nbclient\client.py", line 1204, in execute
    return NotebookClient(nb=nb, resources=resources, km=km, **kwargs).execute()
  File "C:\Users\samia\Downloads\Anaconda\lib\site-packages\nbclient\util.py", line 84, in wrapped
    return just_run(coro(*args, **kwargs))
  File "C:\Users\samia\Downloads\Anaconda\lib\site-packages\nbclient\util.py", line 62, in just_run
    return loop.run_until_complete(coro)
  File "C:\Users\samia\Downloads\Anaconda\lib\asyncio\base_events.py", line 647, in run_until_complete
    return future.result()
  File "C:\Users\samia\Downloads\Anaconda\lib\site-packages\nbclient\client.py", line 663, in async_execute
    await self.async_execute_cell(
  File "C:\Users\samia\Downloads\Anaconda\lib\site-packages\nbclient\client.py", line 965, in async_execute_cell
    await self._check_raise_for_error(cell, cell_index, exec_reply)
  File "C:\Users\samia\Downloads\Anaconda\lib\site-packages\nbclient\client.py", line 862, in _check_raise_for_error
    raise CellExecutionError.from_cell_and_msg(cell, exec_reply_content)
nbclient.exceptions.CellExecutionError: An error occurred while executing the following cell:
------------------
# Gr√°fico

# Dimensiones del gr√°fico
y_max = np.max(r)
fig, ax = plt.subplots(figsize=(10, 8))

custom_xlim = (0, 130)
custom_ylim = (20, 130)

plt.setp(ax, xlim=custom_xlim, ylim=custom_ylim)


# Curvas a graficar
ax.plot(Y, C, label = "Consumo", color = "red") #Demanda agregada

# Eliminar las cantidades de los ejes
ax.yaxis.set_major_locator(plt.NullLocator())   
ax.xaxis.set_major_locator(plt.NullLocator())

# Texto agregado
    # punto de equilibrio
plt.text(80, 95, '$PMgC = ‚ñ≥C/‚ñ≥Y^d = b = 0.5$', fontsize = 13, color = 'black')


# T√≠tulo y leyenda
ax.set(title="Funci√≥n de demanda de Consumo", xlabel= '$Y^d$', ylabel= 'C')
ax.legend() #mostrar leyenda

plt.show()
------------------

[1;31m---------------------------------------------------------------------------[0m
[1;31mNameError[0m                                 Traceback (most recent call last)
Input [1;32mIn [3][0m, in [0;36m<cell line: 4>[1;34m()[0m
[0;32m      1[0m [38;5;66;03m# Gr√°fico[39;00m
[0;32m      2[0m 
[0;32m      3[0m [38;5;66;03m# Dimensiones del gr√°fico[39;00m
[1;32m----> 4[0m y_max [38;5;241m=[39m np[38;5;241m.[39mmax([43mr[49m)
[0;32m      5[0m fig, ax [38;5;241m=[39m plt[38;5;241m.[39msubplots(figsize[38;5;241m=[39m([38;5;241m10[39m, [38;5;241m8[39m))
[0;32m      7[0m custom_xlim [38;5;241m=[39m ([38;5;241m0[39m, [38;5;241m130[39m)

[1;31mNameError[0m: name 'r' is not defined
NameError: name 'r' is not defined

